<?xml version="1.0"?>
<robot xmlns:xacro="http://www.ros.org/wiki/xacro" name="robot_description">

  <xacro:macro name="robot_description" params="enable_joint1 enable_joint2 enable_joint3" >

    <!-- <link name="world">
      <visual>
        <geometry>
          <cylinder length="0.05" radius="0.08"/>
        </geometry>
        <material name="gray">
          <color rgba="0.6 0.6 0.6 1"/>
        </material>
      </visual>
    </link> -->

    <!-- Joint 1 -->
    <xacro:if value="${enable_joint1}" >
      <link name="link1">
        <visual>
          <geometry>
            <cylinder length="0.3" radius="0.04"/>
          </geometry>
          <origin xyz="0 0 0.15" rpy="0 0 0"/>
          <material name="blue">
            <color rgba="0.2 0.2 0.8 1"/>
          </material>
        </visual>
      </link>
      <joint name="joint1" type="revolute">
        <parent link="world"/>
        <child link="link1"/>
        <origin xyz="0 0 0.05" rpy="0 0 0"/>
        <axis xyz="0 0 1"/>
        <limit lower="-1.57" upper="1.57" effort="10" velocity="2"/>
      </joint>
    </xacro:if>

    <!-- Joint 2 -->
    <xacro:if value="${enable_joint2}" >
      <link name="link2">
        <visual>
          <geometry>
            <cylinder length="0.3" radius="0.04"/>
          </geometry>
          <origin xyz="0 0 0.15" rpy="0 0 0"/>
          <material name="green">
            <color rgba="0.2 0.8 0.2 1"/>
          </material>
        </visual>
      </link>
      <joint name="joint2" type="revolute">
        <parent link="link1"/>
        <child link="link2"/>
        <origin xyz="0 0 0.3" rpy="0 0 0"/>
        <axis xyz="0 1 0"/>
        <limit lower="-1.57" upper="1.57" effort="10" velocity="2"/>
      </joint>
    </xacro:if>

      <!-- Joint 3 -->
    <xacro:if value="${enable_joint3}" >
      <link name="link3">
        <visual>
          <geometry>
            <cylinder length="0.3" radius="0.04"/>
          </geometry>
          <origin xyz="0 0 0.15" rpy="0 0 0"/>
          <material name="red">
            <color rgba="0.8 0.2 0.2 1"/>
          </material>
        </visual>
      </link>
      <joint name="joint3" type="revolute">
        <parent link="link2"/>
        <child link="link3"/>
        <origin xyz="0 0 0.3" rpy="0 0 0"/>
        <axis xyz="0 1 0"/>
        <limit lower="-1.57" upper="1.57" effort="10" velocity="2"/>
      </joint>
    </xacro:if>

  </xacro:macro>  

</robot>
